[2024-05-12 02:32:55,179: INFO: stage1_data_ingestion: >>>>>> stage Data Ingestion stage started <<<<<<]
[2024-05-12 02:32:55,181: INFO: file_op_utils: yaml file: config\config.yaml loaded successfully]
[2024-05-12 02:32:55,188: INFO: file_op_utils: yaml file: params.yaml loaded successfully]
[2024-05-12 02:32:55,189: INFO: file_op_utils: created directory at: artifacts]
[2024-05-12 02:32:55,190: INFO: file_op_utils: created directory at: artifacts/data_ingestion]
[2024-05-12 02:32:55,191: INFO: data_ingestion: Downloading data from https://drive.google.com/file/d/18JJ5SvjkqQvRgcSwqAUCSygnDnM8wfwj/view?usp=drive_link into file artifacts/data_ingestion/data.zip]
[2024-05-12 02:37:01,313: INFO: main: >>>>>> stage Data Ingestion stage started <<<<<<]
[2024-05-12 02:37:01,313: INFO: file_op_utils: yaml file: config\config.yaml loaded successfully]
[2024-05-12 02:37:01,313: INFO: file_op_utils: yaml file: params.yaml loaded successfully]
[2024-05-12 02:37:01,313: INFO: file_op_utils: created directory at: artifacts]
[2024-05-12 02:37:01,313: INFO: file_op_utils: created directory at: artifacts/data_ingestion]
[2024-05-12 02:37:01,313: INFO: data_ingestion: Downloading data from https://drive.google.com/file/d/18JJ5SvjkqQvRgcSwqAUCSygnDnM8wfwj/view?usp=drive_link into file artifacts/data_ingestion/data.zip]
[2024-05-12 02:39:08,234: INFO: data_ingestion: Downloaded data from https://drive.google.com/file/d/18JJ5SvjkqQvRgcSwqAUCSygnDnM8wfwj/view?usp=drive_link into file artifacts/data_ingestion/data.zip]
[2024-05-12 02:39:28,590: INFO: main: >>>>>> stage Data Ingestion stage completed <<<<<<

x==========x]
[2024-06-02 18:44:27,329: INFO: main: >>>>>> stage Data Ingestion stage started <<<<<<]
[2024-06-02 18:44:27,345: INFO: file_op_utils: yaml file: config\config.yaml loaded successfully]
[2024-06-02 18:44:27,353: INFO: file_op_utils: yaml file: params.yaml loaded successfully]
[2024-06-02 18:44:27,353: INFO: file_op_utils: created directory at: artifacts]
[2024-06-02 18:44:27,353: INFO: file_op_utils: created directory at: artifacts/data_ingestion]
[2024-06-02 18:44:27,353: INFO: data_ingestion: Downloading data from https://drive.google.com/file/d/18JJ5SvjkqQvRgcSwqAUCSygnDnM8wfwj/view?usp=drive_link into file artifacts/data_ingestion/data.zip]
[2024-06-02 18:47:33,134: INFO: data_ingestion: Downloaded data from https://drive.google.com/file/d/18JJ5SvjkqQvRgcSwqAUCSygnDnM8wfwj/view?usp=drive_link into file artifacts/data_ingestion/data.zip]
[2024-06-02 18:47:57,938: INFO: main: >>>>>> stage Data Ingestion stage completed <<<<<<

x==========x]
[2024-06-02 18:47:57,938: INFO: main: *******************]
[2024-06-02 18:47:57,938: INFO: main: >>>>>> stage Prepare base model started <<<<<<]
[2024-06-02 18:47:57,938: INFO: file_op_utils: yaml file: config\config.yaml loaded successfully]
[2024-06-02 18:47:57,938: INFO: file_op_utils: yaml file: params.yaml loaded successfully]
[2024-06-02 18:47:57,946: INFO: file_op_utils: created directory at: artifacts]
[2024-06-02 18:47:57,946: INFO: file_op_utils: created directory at: artifacts/prepare_base_model]
[2024-06-02 18:48:13,086: WARNING: saving_utils: Compiled the loaded model, but the compiled metrics have yet to be built. `model.compile_metrics` will be empty until you train or evaluate the model.]
[2024-06-02 18:48:14,016: INFO: main: >>>>>> stage Prepare base model completed <<<<<<

x==========x]
[2024-06-03 21:51:53,251: INFO: main: >>>>>> stage Data Ingestion stage started <<<<<<]
[2024-06-03 21:51:53,259: INFO: file_op_utils: yaml file: config\config.yaml loaded successfully]
[2024-06-03 21:51:53,262: INFO: file_op_utils: yaml file: params.yaml loaded successfully]
[2024-06-03 21:51:53,262: INFO: file_op_utils: created directory at: artifacts]
[2024-06-03 21:51:53,265: INFO: file_op_utils: created directory at: artifacts/data_ingestion]
[2024-06-03 21:51:53,265: INFO: data_ingestion: Downloading data from https://drive.google.com/file/d/18JJ5SvjkqQvRgcSwqAUCSygnDnM8wfwj/view?usp=drive_link into file artifacts/data_ingestion/data.zip]
[2024-06-03 21:55:09,841: INFO: data_ingestion: Downloaded data from https://drive.google.com/file/d/18JJ5SvjkqQvRgcSwqAUCSygnDnM8wfwj/view?usp=drive_link into file artifacts/data_ingestion/data.zip]
[2024-06-03 21:56:00,140: INFO: main: >>>>>> stage Data Ingestion stage completed <<<<<<

x==========x]
[2024-06-03 21:56:00,140: INFO: main: *******************]
[2024-06-03 21:56:00,140: INFO: main: >>>>>> stage Prepare base model started <<<<<<]
[2024-06-03 21:56:00,140: INFO: file_op_utils: yaml file: config\config.yaml loaded successfully]
[2024-06-03 21:56:00,156: INFO: file_op_utils: yaml file: params.yaml loaded successfully]
[2024-06-03 21:56:00,156: INFO: file_op_utils: created directory at: artifacts]
[2024-06-03 21:56:00,156: INFO: file_op_utils: created directory at: artifacts/prepare_base_model]
[2024-06-03 21:56:04,309: WARNING: saving_utils: Compiled the loaded model, but the compiled metrics have yet to be built. `model.compile_metrics` will be empty until you train or evaluate the model.]
[2024-06-03 21:56:07,489: INFO: main: >>>>>> stage Prepare base model completed <<<<<<

x==========x]
[2024-06-03 21:56:07,489: INFO: main: *******************]
[2024-06-03 21:56:07,489: INFO: main: >>>>>> stage Training started <<<<<<]
[2024-06-03 21:56:07,503: INFO: file_op_utils: yaml file: config\config.yaml loaded successfully]
[2024-06-03 21:56:07,503: INFO: file_op_utils: yaml file: params.yaml loaded successfully]
[2024-06-03 21:56:07,503: INFO: file_op_utils: created directory at: artifacts]
[2024-06-03 21:56:07,503: INFO: file_op_utils: created directory at: artifacts\training]
[2024-06-03 21:56:11,699: ERROR: main: [WinError 3] The system cannot find the path specified: 'artifacts\\data_ingestion\\kidney-ct-scan-image']
Traceback (most recent call last):
  File "main.py", line 42, in <module>
    model_trainer.main()
  File "c:\users\sneha\documents\projects\kidneynet\src\cnnClassifier\pipeline\stage3_model_training.py", line 20, in main
    training.train_valid_generator()
  File "c:\users\sneha\documents\projects\kidneynet\src\cnnClassifier\components\model_training.py", line 37, in train_valid_generator
    self.valid_generator = valid_datagenerator.flow_from_directory(
  File "C:\Users\Sneha\anaconda3\envs\kidney\lib\site-packages\keras\preprocessing\image.py", line 1648, in flow_from_directory
    return DirectoryIterator(
  File "C:\Users\Sneha\anaconda3\envs\kidney\lib\site-packages\keras\preprocessing\image.py", line 563, in __init__
    for subdir in sorted(os.listdir(directory)):
FileNotFoundError: [WinError 3] The system cannot find the path specified: 'artifacts\\data_ingestion\\kidney-ct-scan-image'
[2024-06-03 22:12:52,963: INFO: main: >>>>>> stage Data Ingestion stage started <<<<<<]
[2024-06-03 22:12:52,963: INFO: file_op_utils: yaml file: config\config.yaml loaded successfully]
[2024-06-03 22:12:52,963: INFO: file_op_utils: yaml file: params.yaml loaded successfully]
[2024-06-03 22:12:52,963: INFO: file_op_utils: created directory at: artifacts]
[2024-06-03 22:12:52,963: INFO: file_op_utils: created directory at: artifacts/data_ingestion]
[2024-06-03 22:12:52,963: INFO: data_ingestion: Downloading data from https://drive.google.com/file/d/18JJ5SvjkqQvRgcSwqAUCSygnDnM8wfwj/view?usp=drive_link into file artifacts/data_ingestion/data.zip]
[2024-06-03 22:16:03,568: INFO: main: *******************]
[2024-06-03 22:16:03,568: INFO: main: >>>>>> stage Training started <<<<<<]
[2024-06-03 22:16:03,568: INFO: file_op_utils: yaml file: config\config.yaml loaded successfully]
[2024-06-03 22:16:03,568: INFO: file_op_utils: yaml file: params.yaml loaded successfully]
[2024-06-03 22:16:03,568: INFO: file_op_utils: created directory at: artifacts]
[2024-06-03 22:16:03,568: INFO: file_op_utils: created directory at: artifacts\training]
[2024-06-03 22:44:23,973: INFO: main: >>>>>> stage Training completed <<<<<<

x==========x]
[2024-06-03 22:44:23,973: INFO: main: *******************]
[2024-06-03 22:44:23,973: INFO: main: >>>>>> stage Evaluation stage started <<<<<<]
[2024-06-03 22:44:23,973: INFO: file_op_utils: yaml file: config\config.yaml loaded successfully]
[2024-06-03 22:44:23,985: INFO: file_op_utils: yaml file: params.yaml loaded successfully]
[2024-06-03 22:44:23,987: INFO: file_op_utils: created directory at: artifacts]
[2024-06-03 22:54:33,789: INFO: file_op_utils: json file saved at: scores.json]
[2024-06-03 22:54:33,792: INFO: file_op_utils: json file saved at: scores.json]
[2024-06-03 22:54:33,794: INFO: main: >>>>>> stage Evaluation stage completed <<<<<<

x==========x]
[2024-06-03 23:10:53,597: INFO: main: *******************]
[2024-06-03 23:10:53,597: INFO: main: >>>>>> stage Training started <<<<<<]
[2024-06-03 23:10:53,613: INFO: file_op_utils: yaml file: config\config.yaml loaded successfully]
[2024-06-03 23:10:53,613: INFO: file_op_utils: yaml file: params.yaml loaded successfully]
[2024-06-03 23:10:53,613: INFO: file_op_utils: created directory at: artifacts]
[2024-06-03 23:10:53,623: INFO: file_op_utils: created directory at: artifacts\training]
[2024-06-03 23:44:32,617: INFO: main: >>>>>> stage Training completed <<<<<<

x==========x]
[2024-06-03 23:44:32,619: INFO: main: *******************]
[2024-06-03 23:44:32,619: INFO: main: >>>>>> stage Evaluation stage started <<<<<<]
[2024-06-03 23:44:32,627: INFO: file_op_utils: yaml file: config\config.yaml loaded successfully]
[2024-06-03 23:44:32,632: INFO: file_op_utils: yaml file: params.yaml loaded successfully]
[2024-06-03 23:44:32,634: INFO: file_op_utils: created directory at: artifacts]
[2024-06-03 23:54:29,274: INFO: file_op_utils: json file saved at: scores.json]
[2024-06-03 23:54:29,278: INFO: file_op_utils: json file saved at: scores.json]
[2024-06-03 23:54:29,278: INFO: main: >>>>>> stage Evaluation stage completed <<<<<<

x==========x]
[2024-06-04 00:36:38,052: INFO: main: *******************]
[2024-06-04 00:36:38,052: INFO: main: >>>>>> stage Training started <<<<<<]
[2024-06-04 00:36:38,052: INFO: file_op_utils: yaml file: config\config.yaml loaded successfully]
[2024-06-04 00:36:38,052: INFO: file_op_utils: yaml file: params.yaml loaded successfully]
[2024-06-04 00:36:38,052: INFO: file_op_utils: created directory at: artifacts]
[2024-06-04 00:36:38,060: INFO: file_op_utils: created directory at: artifacts\training]
[2024-06-04 00:36:39,478: ERROR: main: [WinError 3] The system cannot find the path specified: 'artifacts\\data_ingestion\\CT-KIDNEY-DATASET-Normal-Cyst-Tumor-Stone']
Traceback (most recent call last):
  File "main.py", line 42, in <module>
    model_trainer.main()
  File "c:\users\sneha\documents\projects\kidneynet\src\cnnClassifier\pipeline\stage3_model_training.py", line 20, in main
    training.train_valid_generator()
  File "c:\users\sneha\documents\projects\kidneynet\src\cnnClassifier\components\model_training.py", line 37, in train_valid_generator
    self.valid_generator = valid_datagenerator.flow_from_directory(
  File "C:\Users\Sneha\anaconda3\envs\kidney\lib\site-packages\keras\preprocessing\image.py", line 1648, in flow_from_directory
    return DirectoryIterator(
  File "C:\Users\Sneha\anaconda3\envs\kidney\lib\site-packages\keras\preprocessing\image.py", line 563, in __init__
    for subdir in sorted(os.listdir(directory)):
FileNotFoundError: [WinError 3] The system cannot find the path specified: 'artifacts\\data_ingestion\\CT-KIDNEY-DATASET-Normal-Cyst-Tumor-Stone'
[2024-06-04 00:37:23,370: INFO: main: *******************]
[2024-06-04 00:37:23,370: INFO: main: >>>>>> stage Training started <<<<<<]
[2024-06-04 00:37:23,370: INFO: file_op_utils: yaml file: config\config.yaml loaded successfully]
[2024-06-04 00:37:23,370: INFO: file_op_utils: yaml file: params.yaml loaded successfully]
[2024-06-04 00:37:23,370: INFO: file_op_utils: created directory at: artifacts]
[2024-06-04 00:37:23,370: INFO: file_op_utils: created directory at: artifacts\training]
[2024-06-04 01:11:25,883: INFO: main: >>>>>> stage Training completed <<<<<<

x==========x]
[2024-06-04 01:11:25,883: INFO: main: *******************]
[2024-06-04 01:11:25,883: INFO: main: >>>>>> stage Evaluation stage started <<<<<<]
[2024-06-04 01:11:25,883: INFO: file_op_utils: yaml file: config\config.yaml loaded successfully]
[2024-06-04 01:11:25,896: INFO: file_op_utils: yaml file: params.yaml loaded successfully]
[2024-06-04 01:11:25,898: INFO: file_op_utils: created directory at: artifacts]
[2024-06-04 01:20:44,310: INFO: file_op_utils: json file saved at: scores.json]
[2024-06-04 01:20:44,310: INFO: file_op_utils: json file saved at: scores.json]
[2024-06-04 01:20:51,537: WARNING: save: Found untraced functions such as _jit_compiled_convolution_op, _jit_compiled_convolution_op, _jit_compiled_convolution_op, _jit_compiled_convolution_op, _jit_compiled_convolution_op while saving (showing 5 of 41). These functions will not be directly callable after loading.]
[2024-06-04 01:20:54,484: INFO: builder_impl: Assets written to: C:\Users\Sneha\AppData\Local\Temp\tmpiwt2jjt8\model\data\model\assets]
[2024-06-04 01:21:04,823: ERROR: main: The configured tracking uri scheme: 'file' is invalid for use with the proxy mlflow-artifact scheme. The allowed tracking schemes are: {'http', 'https'}]
Traceback (most recent call last):
  File "main.py", line 56, in <module>
    model_evalution.main()
  File "c:\users\sneha\documents\projects\kidneynet\src\cnnClassifier\pipeline\stage4_model_evaluation.py", line 20, in main
    evaluation.log_into_mlflow()
  File "c:\users\sneha\documents\projects\kidneynet\src\cnnClassifier\components\model_evaluation_mlflow.py", line 74, in log_into_mlflow
    mlflow.keras.log_model(self.model, "model")
  File "C:\Users\Sneha\anaconda3\envs\kidney\lib\site-packages\mlflow\tensorflow\__init__.py", line 222, in log_model
    return Model.log(
  File "C:\Users\Sneha\anaconda3\envs\kidney\lib\site-packages\mlflow\models\model.py", line 552, in log
    mlflow.tracking.fluent.log_artifacts(local_path, mlflow_model.artifact_path)
  File "C:\Users\Sneha\anaconda3\envs\kidney\lib\site-packages\mlflow\tracking\fluent.py", line 817, in log_artifacts
    MlflowClient().log_artifacts(run_id, local_dir, artifact_path)
  File "C:\Users\Sneha\anaconda3\envs\kidney\lib\site-packages\mlflow\tracking\client.py", line 1069, in log_artifacts
    self._tracking_client.log_artifacts(run_id, local_dir, artifact_path)
  File "C:\Users\Sneha\anaconda3\envs\kidney\lib\site-packages\mlflow\tracking\_tracking_service\client.py", line 448, in log_artifacts
    self._get_artifact_repo(run_id).log_artifacts(local_dir, artifact_path)
  File "C:\Users\Sneha\anaconda3\envs\kidney\lib\site-packages\mlflow\tracking\_tracking_service\client.py", line 416, in _get_artifact_repo
    artifact_repo = get_artifact_repository(artifact_uri)
  File "C:\Users\Sneha\anaconda3\envs\kidney\lib\site-packages\mlflow\store\artifact\artifact_repository_registry.py", line 106, in get_artifact_repository
    return _artifact_repository_registry.get_artifact_repository(artifact_uri)
  File "C:\Users\Sneha\anaconda3\envs\kidney\lib\site-packages\mlflow\store\artifact\artifact_repository_registry.py", line 72, in get_artifact_repository
    return repository(artifact_uri)
  File "C:\Users\Sneha\anaconda3\envs\kidney\lib\site-packages\mlflow\store\artifact\mlflow_artifacts_repo.py", line 45, in __init__
    super().__init__(self.resolve_uri(artifact_uri, get_tracking_uri()))
  File "C:\Users\Sneha\anaconda3\envs\kidney\lib\site-packages\mlflow\store\artifact\mlflow_artifacts_repo.py", line 59, in resolve_uri
    _validate_uri_scheme(track_parse.scheme)
  File "C:\Users\Sneha\anaconda3\envs\kidney\lib\site-packages\mlflow\store\artifact\mlflow_artifacts_repo.py", line 35, in _validate_uri_scheme
    raise MlflowException(
mlflow.exceptions.MlflowException: The configured tracking uri scheme: 'file' is invalid for use with the proxy mlflow-artifact scheme. The allowed tracking schemes are: {'http', 'https'}
[2024-06-04 12:41:53,364: INFO: main: *******************]
[2024-06-04 12:41:53,364: INFO: main: >>>>>> stage Training started <<<<<<]
[2024-06-04 12:41:53,372: INFO: file_op_utils: yaml file: config\config.yaml loaded successfully]
[2024-06-04 12:41:53,380: INFO: file_op_utils: yaml file: params.yaml loaded successfully]
[2024-06-04 12:41:53,380: INFO: file_op_utils: created directory at: artifacts]
[2024-06-04 12:41:53,380: INFO: file_op_utils: created directory at: artifacts\training]
[2024-06-04 12:42:02,899: INFO: main: >>>>>> stage Training completed <<<<<<

x==========x]
[2024-06-04 12:42:02,899: INFO: main: *******************]
[2024-06-04 12:42:02,899: INFO: main: >>>>>> stage Evaluation stage started <<<<<<]
[2024-06-04 12:42:02,908: INFO: file_op_utils: yaml file: config\config.yaml loaded successfully]
[2024-06-04 12:42:02,908: INFO: file_op_utils: yaml file: params.yaml loaded successfully]
[2024-06-04 12:42:02,916: INFO: file_op_utils: created directory at: artifacts]
[2024-06-04 12:42:07,781: INFO: file_op_utils: json file saved at: scores.json]
[2024-06-04 12:42:07,789: INFO: file_op_utils: json file saved at: scores.json]
[2024-06-04 12:42:07,976: ERROR: main: Could not find experiment with ID 0]
Traceback (most recent call last):
  File "main.py", line 56, in <module>
    model_evalution.main()
  File "c:\users\sneha\documents\projects\kidneynet\src\cnnClassifier\pipeline\stage4_model_evaluation.py", line 20, in main
    evaluation.log_into_mlflow()
  File "c:\users\sneha\documents\projects\kidneynet\src\cnnClassifier\components\model_evaluation_mlflow.py", line 60, in log_into_mlflow
    with mlflow.start_run():
  File "C:\Users\Sneha\anaconda3\envs\kidney\lib\site-packages\mlflow\tracking\fluent.py", line 350, in start_run
    active_run_obj = client.create_run(
  File "C:\Users\Sneha\anaconda3\envs\kidney\lib\site-packages\mlflow\tracking\client.py", line 275, in create_run
    return self._tracking_client.create_run(experiment_id, start_time, tags, run_name)
  File "C:\Users\Sneha\anaconda3\envs\kidney\lib\site-packages\mlflow\tracking\_tracking_service\client.py", line 131, in create_run
    return self.store.create_run(
  File "C:\Users\Sneha\anaconda3\envs\kidney\lib\site-packages\mlflow\store\tracking\file_store.py", line 579, in create_run
    experiment = self.get_experiment(experiment_id)
  File "C:\Users\Sneha\anaconda3\envs\kidney\lib\site-packages\mlflow\store\tracking\file_store.py", line 410, in get_experiment
    experiment = self._get_experiment(experiment_id)
  File "C:\Users\Sneha\anaconda3\envs\kidney\lib\site-packages\mlflow\store\tracking\file_store.py", line 379, in _get_experiment
    raise MlflowException(
mlflow.exceptions.MlflowException: Could not find experiment with ID 0
[2024-06-04 12:44:28,004: INFO: main: *******************]
[2024-06-04 12:44:28,004: INFO: main: >>>>>> stage Training started <<<<<<]
[2024-06-04 12:44:28,004: INFO: file_op_utils: yaml file: config\config.yaml loaded successfully]
[2024-06-04 12:44:28,012: INFO: file_op_utils: yaml file: params.yaml loaded successfully]
[2024-06-04 12:44:28,012: INFO: file_op_utils: created directory at: artifacts]
[2024-06-04 12:44:28,012: INFO: file_op_utils: created directory at: artifacts\training]
[2024-06-04 12:44:28,012: ERROR: main: No file or directory found at artifacts\prepare_base_model\base_model_updated.h5]
Traceback (most recent call last):
  File "main.py", line 42, in <module>
    model_trainer.main()
  File "c:\users\sneha\documents\projects\kidneynet\src\cnnClassifier\pipeline\stage3_model_training.py", line 19, in main
    training.get_base_model()
  File "c:\users\sneha\documents\projects\kidneynet\src\cnnClassifier\components\model_training.py", line 16, in get_base_model
    self.model = tf.keras.models.load_model(
  File "C:\Users\Sneha\anaconda3\envs\kidney\lib\site-packages\keras\saving\saving_api.py", line 212, in load_model
    return legacy_sm_saving_lib.load_model(
  File "C:\Users\Sneha\anaconda3\envs\kidney\lib\site-packages\keras\utils\traceback_utils.py", line 70, in error_handler
    raise e.with_traceback(filtered_tb) from None
  File "C:\Users\Sneha\anaconda3\envs\kidney\lib\site-packages\keras\saving\legacy\save.py", line 230, in load_model
    raise IOError(
OSError: No file or directory found at artifacts\prepare_base_model\base_model_updated.h5
[2024-06-04 12:44:57,639: INFO: main: *******************]
[2024-06-04 12:44:57,639: INFO: main: >>>>>> stage Prepare base model started <<<<<<]
[2024-06-04 12:44:57,639: INFO: file_op_utils: yaml file: config\config.yaml loaded successfully]
[2024-06-04 12:44:57,648: INFO: file_op_utils: yaml file: params.yaml loaded successfully]
[2024-06-04 12:44:57,648: INFO: file_op_utils: created directory at: artifacts]
[2024-06-04 12:44:57,648: INFO: file_op_utils: created directory at: artifacts/prepare_base_model]
[2024-06-04 12:44:59,100: WARNING: saving_utils: Compiled the loaded model, but the compiled metrics have yet to be built. `model.compile_metrics` will be empty until you train or evaluate the model.]
[2024-06-04 12:45:00,169: INFO: main: >>>>>> stage Prepare base model completed <<<<<<

x==========x]
[2024-06-04 12:45:00,169: INFO: main: *******************]
[2024-06-04 12:45:00,169: INFO: main: >>>>>> stage Training started <<<<<<]
[2024-06-04 12:45:00,169: INFO: file_op_utils: yaml file: config\config.yaml loaded successfully]
[2024-06-04 12:45:00,169: INFO: file_op_utils: yaml file: params.yaml loaded successfully]
[2024-06-04 12:45:00,169: INFO: file_op_utils: created directory at: artifacts]
[2024-06-04 12:45:00,169: INFO: file_op_utils: created directory at: artifacts\training]
[2024-06-04 12:45:10,370: INFO: main: >>>>>> stage Training completed <<<<<<

x==========x]
[2024-06-04 12:45:10,370: INFO: main: *******************]
[2024-06-04 12:45:10,370: INFO: main: >>>>>> stage Evaluation stage started <<<<<<]
[2024-06-04 12:45:10,370: INFO: file_op_utils: yaml file: config\config.yaml loaded successfully]
[2024-06-04 12:45:10,370: INFO: file_op_utils: yaml file: params.yaml loaded successfully]
[2024-06-04 12:45:10,370: INFO: file_op_utils: created directory at: artifacts]
[2024-06-04 12:45:15,873: INFO: file_op_utils: json file saved at: scores.json]
[2024-06-04 12:45:15,881: INFO: file_op_utils: json file saved at: scores.json]
[2024-06-04 12:45:16,083: ERROR: main: Could not find experiment with ID 0]
Traceback (most recent call last):
  File "main.py", line 56, in <module>
    model_evalution.main()
  File "c:\users\sneha\documents\projects\kidneynet\src\cnnClassifier\pipeline\stage4_model_evaluation.py", line 20, in main
    evaluation.log_into_mlflow()
  File "c:\users\sneha\documents\projects\kidneynet\src\cnnClassifier\components\model_evaluation_mlflow.py", line 60, in log_into_mlflow
    with mlflow.start_run():
  File "C:\Users\Sneha\anaconda3\envs\kidney\lib\site-packages\mlflow\tracking\fluent.py", line 350, in start_run
    active_run_obj = client.create_run(
  File "C:\Users\Sneha\anaconda3\envs\kidney\lib\site-packages\mlflow\tracking\client.py", line 275, in create_run
    return self._tracking_client.create_run(experiment_id, start_time, tags, run_name)
  File "C:\Users\Sneha\anaconda3\envs\kidney\lib\site-packages\mlflow\tracking\_tracking_service\client.py", line 131, in create_run
    return self.store.create_run(
  File "C:\Users\Sneha\anaconda3\envs\kidney\lib\site-packages\mlflow\store\tracking\file_store.py", line 579, in create_run
    experiment = self.get_experiment(experiment_id)
  File "C:\Users\Sneha\anaconda3\envs\kidney\lib\site-packages\mlflow\store\tracking\file_store.py", line 410, in get_experiment
    experiment = self._get_experiment(experiment_id)
  File "C:\Users\Sneha\anaconda3\envs\kidney\lib\site-packages\mlflow\store\tracking\file_store.py", line 379, in _get_experiment
    raise MlflowException(
mlflow.exceptions.MlflowException: Could not find experiment with ID 0
[2024-06-04 12:51:50,149: INFO: main: *******************]
[2024-06-04 12:51:50,149: INFO: main: >>>>>> stage Prepare base model started <<<<<<]
[2024-06-04 12:51:50,151: INFO: file_op_utils: yaml file: config\config.yaml loaded successfully]
[2024-06-04 12:51:50,151: INFO: file_op_utils: yaml file: params.yaml loaded successfully]
[2024-06-04 12:51:50,151: INFO: file_op_utils: created directory at: artifacts]
[2024-06-04 12:51:50,151: INFO: file_op_utils: created directory at: artifacts/prepare_base_model]
[2024-06-04 12:51:51,440: WARNING: saving_utils: Compiled the loaded model, but the compiled metrics have yet to be built. `model.compile_metrics` will be empty until you train or evaluate the model.]
[2024-06-04 12:51:52,441: INFO: main: >>>>>> stage Prepare base model completed <<<<<<

x==========x]
[2024-06-04 12:51:52,441: INFO: main: *******************]
[2024-06-04 12:51:52,441: INFO: main: >>>>>> stage Training started <<<<<<]
[2024-06-04 12:51:52,448: INFO: file_op_utils: yaml file: config\config.yaml loaded successfully]
[2024-06-04 12:51:52,448: INFO: file_op_utils: yaml file: params.yaml loaded successfully]
[2024-06-04 12:51:52,448: INFO: file_op_utils: created directory at: artifacts]
[2024-06-04 12:51:52,448: INFO: file_op_utils: created directory at: artifacts\training]
[2024-06-04 12:51:54,074: ERROR: main: [WinError 3] The system cannot find the path specified: 'artifacts\\data_ingestion\\CT-KIDNEY-DATASET-Normal-Cyst-Tumor-Stone']
Traceback (most recent call last):
  File "main.py", line 42, in <module>
    model_trainer.main()
  File "c:\users\sneha\documents\projects\kidneynet\src\cnnClassifier\pipeline\stage3_model_training.py", line 20, in main
    training.train_valid_generator()
  File "c:\users\sneha\documents\projects\kidneynet\src\cnnClassifier\components\model_training.py", line 37, in train_valid_generator
    self.valid_generator = valid_datagenerator.flow_from_directory(
  File "C:\Users\Sneha\anaconda3\envs\kidney\lib\site-packages\keras\preprocessing\image.py", line 1648, in flow_from_directory
    return DirectoryIterator(
  File "C:\Users\Sneha\anaconda3\envs\kidney\lib\site-packages\keras\preprocessing\image.py", line 563, in __init__
    for subdir in sorted(os.listdir(directory)):
FileNotFoundError: [WinError 3] The system cannot find the path specified: 'artifacts\\data_ingestion\\CT-KIDNEY-DATASET-Normal-Cyst-Tumor-Stone'
[2024-06-04 12:52:23,637: INFO: main: >>>>>> stage Data Ingestion stage started <<<<<<]
[2024-06-04 12:52:23,637: INFO: file_op_utils: yaml file: config\config.yaml loaded successfully]
[2024-06-04 12:52:23,637: INFO: file_op_utils: yaml file: params.yaml loaded successfully]
[2024-06-04 12:52:23,637: INFO: file_op_utils: created directory at: artifacts]
[2024-06-04 12:52:23,637: INFO: file_op_utils: created directory at: artifacts/data_ingestion]
[2024-06-04 12:52:23,637: INFO: data_ingestion: Downloading data from https://drive.google.com/file/d/18JJ5SvjkqQvRgcSwqAUCSygnDnM8wfwj/view?usp=drive_link into file artifacts/data_ingestion/data.zip]
[2024-06-04 12:56:29,124: INFO: data_ingestion: Downloaded data from https://drive.google.com/file/d/18JJ5SvjkqQvRgcSwqAUCSygnDnM8wfwj/view?usp=drive_link into file artifacts/data_ingestion/data.zip]
[2024-06-04 12:56:49,553: INFO: main: >>>>>> stage Data Ingestion stage completed <<<<<<

x==========x]
[2024-06-04 12:56:49,553: INFO: main: *******************]
[2024-06-04 12:56:49,553: INFO: main: >>>>>> stage Prepare base model started <<<<<<]
[2024-06-04 12:56:49,556: INFO: file_op_utils: yaml file: config\config.yaml loaded successfully]
[2024-06-04 12:56:49,562: INFO: file_op_utils: yaml file: params.yaml loaded successfully]
[2024-06-04 12:56:49,563: INFO: file_op_utils: created directory at: artifacts]
[2024-06-04 12:56:49,564: INFO: file_op_utils: created directory at: artifacts/prepare_base_model]
[2024-06-04 12:56:51,329: WARNING: saving_utils: Compiled the loaded model, but the compiled metrics have yet to be built. `model.compile_metrics` will be empty until you train or evaluate the model.]
[2024-06-04 12:56:53,054: INFO: main: >>>>>> stage Prepare base model completed <<<<<<

x==========x]
[2024-06-04 12:56:53,054: INFO: main: *******************]
[2024-06-04 12:56:53,054: INFO: main: >>>>>> stage Training started <<<<<<]
[2024-06-04 12:56:53,054: INFO: file_op_utils: yaml file: config\config.yaml loaded successfully]
[2024-06-04 12:56:53,054: INFO: file_op_utils: yaml file: params.yaml loaded successfully]
[2024-06-04 12:56:53,054: INFO: file_op_utils: created directory at: artifacts]
[2024-06-04 12:56:53,069: INFO: file_op_utils: created directory at: artifacts\training]
[2024-06-04 13:50:44,013: INFO: main: >>>>>> stage Training completed <<<<<<

x==========x]
[2024-06-04 13:50:44,013: INFO: main: *******************]
[2024-06-04 13:50:44,013: INFO: main: >>>>>> stage Evaluation stage started <<<<<<]
[2024-06-04 13:50:44,029: INFO: file_op_utils: yaml file: config\config.yaml loaded successfully]
[2024-06-04 13:50:44,029: INFO: file_op_utils: yaml file: params.yaml loaded successfully]
[2024-06-04 13:50:44,029: INFO: file_op_utils: created directory at: artifacts]
[2024-06-04 13:58:35,656: INFO: file_op_utils: json file saved at: scores.json]
[2024-06-04 13:58:35,656: INFO: file_op_utils: json file saved at: scores.json]
[2024-06-04 13:58:42,864: WARNING: save: Found untraced functions such as _jit_compiled_convolution_op, _jit_compiled_convolution_op, _jit_compiled_convolution_op, _jit_compiled_convolution_op, _jit_compiled_convolution_op while saving (showing 5 of 41). These functions will not be directly callable after loading.]
[2024-06-04 13:58:45,262: INFO: builder_impl: Assets written to: C:\Users\Sneha\AppData\Local\Temp\tmpyuq49z0r\model\data\model\assets]
[2024-06-04 13:58:56,505: INFO: dir_util: creating C:\Users\Sneha\Documents\Projects\KidneyNet\mlruns\0\9a0fb77a4b0242c29c778e1c5e656715\artifacts\model\data]
[2024-06-04 13:58:56,505: INFO: dir_util: creating C:\Users\Sneha\Documents\Projects\KidneyNet\mlruns\0\9a0fb77a4b0242c29c778e1c5e656715\artifacts\model\data\model]
[2024-06-04 13:58:56,505: INFO: dir_util: creating C:\Users\Sneha\Documents\Projects\KidneyNet\mlruns\0\9a0fb77a4b0242c29c778e1c5e656715\artifacts\model\data\model\assets]
[2024-06-04 13:58:56,523: INFO: dir_util: creating C:\Users\Sneha\Documents\Projects\KidneyNet\mlruns\0\9a0fb77a4b0242c29c778e1c5e656715\artifacts\model\data\model\variables]
[2024-06-04 13:58:56,652: INFO: main: >>>>>> stage Evaluation stage completed <<<<<<

x==========x]
[2024-06-04 20:41:25,744: INFO: stage1_data_ingestion: >>>>>> stage Data Ingestion stage started <<<<<<]
[2024-06-04 20:41:25,747: INFO: file_op_utils: yaml file: config\config.yaml loaded successfully]
[2024-06-04 20:41:25,752: INFO: file_op_utils: yaml file: params.yaml loaded successfully]
[2024-06-04 20:41:25,752: INFO: file_op_utils: created directory at: artifacts]
[2024-06-04 20:41:25,752: INFO: file_op_utils: created directory at: artifacts/data_ingestion]
[2024-06-04 20:41:25,752: INFO: data_ingestion: Downloading data from https://drive.google.com/file/d/18JJ5SvjkqQvRgcSwqAUCSygnDnM8wfwj/view?usp=drive_link into file artifacts/data_ingestion/data.zip]
[2024-06-04 20:42:41,101: INFO: stage1_data_ingestion: >>>>>> stage Data Ingestion stage started <<<<<<]
[2024-06-04 20:42:41,101: INFO: file_op_utils: yaml file: config\config.yaml loaded successfully]
[2024-06-04 20:42:41,109: INFO: file_op_utils: yaml file: params.yaml loaded successfully]
[2024-06-04 20:42:41,110: INFO: file_op_utils: created directory at: artifacts]
[2024-06-04 20:42:41,110: INFO: file_op_utils: created directory at: artifacts/data_ingestion]
[2024-06-04 20:42:41,110: INFO: data_ingestion: Downloading data from https://drive.google.com/file/d/18JJ5SvjkqQvRgcSwqAUCSygnDnM8wfwj/view?usp=drive_link into file artifacts/data_ingestion/data.zip]
[2024-06-04 20:45:01,288: INFO: data_ingestion: Downloaded data from https://drive.google.com/file/d/18JJ5SvjkqQvRgcSwqAUCSygnDnM8wfwj/view?usp=drive_link into file artifacts/data_ingestion/data.zip]
[2024-06-04 20:45:49,824: INFO: stage1_data_ingestion: >>>>>> stage Data Ingestion stage completed <<<<<<

x==========x]
[2024-06-04 20:50:09,045: INFO: stage2_prepare_base_model: *******************]
[2024-06-04 20:50:09,045: INFO: stage2_prepare_base_model: >>>>>> stage Prepare base model started <<<<<<]
[2024-06-04 20:50:09,045: INFO: file_op_utils: yaml file: config\config.yaml loaded successfully]
[2024-06-04 20:50:09,060: INFO: file_op_utils: yaml file: params.yaml loaded successfully]
[2024-06-04 20:50:09,061: INFO: file_op_utils: created directory at: artifacts]
[2024-06-04 20:50:09,061: INFO: file_op_utils: created directory at: artifacts/prepare_base_model]
[2024-06-04 20:50:12,816: WARNING: saving_utils: Compiled the loaded model, but the compiled metrics have yet to be built. `model.compile_metrics` will be empty until you train or evaluate the model.]
[2024-06-04 20:50:15,593: INFO: stage2_prepare_base_model: >>>>>> stage Prepare base model completed <<<<<<

x==========x]
[2024-06-04 21:03:30,729: INFO: stage2_prepare_base_model: *******************]
[2024-06-04 21:03:30,729: INFO: stage2_prepare_base_model: >>>>>> stage Prepare base model started <<<<<<]
[2024-06-04 21:03:30,729: INFO: file_op_utils: yaml file: config\config.yaml loaded successfully]
[2024-06-04 21:03:30,729: INFO: file_op_utils: yaml file: params.yaml loaded successfully]
[2024-06-04 21:03:30,729: INFO: file_op_utils: created directory at: artifacts]
[2024-06-04 21:03:30,729: INFO: file_op_utils: created directory at: artifacts/prepare_base_model]
[2024-06-04 21:03:31,926: WARNING: saving_utils: Compiled the loaded model, but the compiled metrics have yet to be built. `model.compile_metrics` will be empty until you train or evaluate the model.]
[2024-06-04 21:03:32,807: INFO: stage2_prepare_base_model: >>>>>> stage Prepare base model completed <<<<<<

x==========x]
[2024-06-04 21:26:34,260: INFO: stage2_prepare_base_model: *******************]
[2024-06-04 21:26:34,260: INFO: stage2_prepare_base_model: >>>>>> stage Prepare base model started <<<<<<]
[2024-06-04 21:26:34,275: INFO: file_op_utils: yaml file: config\config.yaml loaded successfully]
[2024-06-04 21:26:34,275: INFO: file_op_utils: yaml file: params.yaml loaded successfully]
[2024-06-04 21:26:34,275: INFO: file_op_utils: created directory at: artifacts]
[2024-06-04 21:26:34,275: INFO: file_op_utils: created directory at: artifacts/prepare_base_model]
[2024-06-04 21:26:37,843: WARNING: saving_utils: Compiled the loaded model, but the compiled metrics have yet to be built. `model.compile_metrics` will be empty until you train or evaluate the model.]
[2024-06-04 21:26:40,778: INFO: stage2_prepare_base_model: >>>>>> stage Prepare base model completed <<<<<<

x==========x]
[2024-06-04 21:33:09,484: INFO: stage2_prepare_base_model: *******************]
[2024-06-04 21:33:09,484: INFO: stage2_prepare_base_model: >>>>>> stage Prepare base model started <<<<<<]
[2024-06-04 21:33:09,484: INFO: file_op_utils: yaml file: config\config.yaml loaded successfully]
[2024-06-04 21:33:09,484: INFO: file_op_utils: yaml file: params.yaml loaded successfully]
[2024-06-04 21:33:09,484: INFO: file_op_utils: created directory at: artifacts]
[2024-06-04 21:33:09,484: INFO: file_op_utils: created directory at: artifacts/prepare_base_model]
[2024-06-04 21:33:10,503: WARNING: saving_utils: Compiled the loaded model, but the compiled metrics have yet to be built. `model.compile_metrics` will be empty until you train or evaluate the model.]
[2024-06-04 21:33:11,190: INFO: stage2_prepare_base_model: >>>>>> stage Prepare base model completed <<<<<<

x==========x]
[2024-06-04 21:37:49,841: INFO: stage2_prepare_base_model: *******************]
[2024-06-04 21:37:49,841: INFO: stage2_prepare_base_model: >>>>>> stage Prepare base model started <<<<<<]
[2024-06-04 21:37:49,841: INFO: file_op_utils: yaml file: config\config.yaml loaded successfully]
[2024-06-04 21:37:49,857: INFO: file_op_utils: yaml file: params.yaml loaded successfully]
[2024-06-04 21:37:49,857: INFO: file_op_utils: created directory at: artifacts]
[2024-06-04 21:37:49,857: INFO: file_op_utils: created directory at: artifacts/prepare_base_model]
[2024-06-04 21:37:50,800: WARNING: saving_utils: Compiled the loaded model, but the compiled metrics have yet to be built. `model.compile_metrics` will be empty until you train or evaluate the model.]
[2024-06-04 21:37:51,509: INFO: stage2_prepare_base_model: >>>>>> stage Prepare base model completed <<<<<<

x==========x]
[2024-06-04 21:37:59,422: INFO: stage3_model_training: *******************]
[2024-06-04 21:37:59,422: INFO: stage3_model_training: >>>>>> stage Training started <<<<<<]
[2024-06-04 21:37:59,422: INFO: file_op_utils: yaml file: config\config.yaml loaded successfully]
[2024-06-04 21:37:59,422: INFO: file_op_utils: yaml file: params.yaml loaded successfully]
[2024-06-04 21:37:59,422: INFO: file_op_utils: created directory at: artifacts]
[2024-06-04 21:37:59,438: INFO: file_op_utils: created directory at: artifacts\training]
[2024-06-04 22:23:14,218: INFO: stage3_model_training: >>>>>> stage Training completed <<<<<<

x==========x]
[2024-06-04 22:23:39,264: INFO: stage4_model_evaluation: *******************]
[2024-06-04 22:23:39,265: INFO: stage4_model_evaluation: >>>>>> stage Evaluation stage started <<<<<<]
[2024-06-04 22:23:39,272: INFO: file_op_utils: yaml file: config\config.yaml loaded successfully]
[2024-06-04 22:23:39,277: INFO: file_op_utils: yaml file: params.yaml loaded successfully]
[2024-06-04 22:23:39,279: INFO: file_op_utils: created directory at: artifacts]
[2024-06-04 22:37:37,071: INFO: file_op_utils: json file saved at: scores.json]
[2024-06-04 22:37:37,073: INFO: file_op_utils: json file saved at: scores.json]
[2024-06-04 22:37:58,304: WARNING: save: Found untraced functions such as _jit_compiled_convolution_op, _jit_compiled_convolution_op, _jit_compiled_convolution_op, _jit_compiled_convolution_op, _jit_compiled_convolution_op while saving (showing 5 of 41). These functions will not be directly callable after loading.]
[2024-06-04 22:38:04,589: INFO: builder_impl: Assets written to: C:\Users\Sneha\AppData\Local\Temp\tmp8hc85dqa\model\data\model\assets]
[2024-06-04 22:38:21,213: INFO: dir_util: creating C:\Users\Sneha\Documents\Projects\KidneyNet\mlruns\0\60b5542ceef141a7a4077f71eb74bcea\artifacts\model\data]
[2024-06-04 22:38:21,215: INFO: dir_util: creating C:\Users\Sneha\Documents\Projects\KidneyNet\mlruns\0\60b5542ceef141a7a4077f71eb74bcea\artifacts\model\data\model]
[2024-06-04 22:38:21,216: INFO: dir_util: creating C:\Users\Sneha\Documents\Projects\KidneyNet\mlruns\0\60b5542ceef141a7a4077f71eb74bcea\artifacts\model\data\model\assets]
[2024-06-04 22:38:21,225: INFO: dir_util: creating C:\Users\Sneha\Documents\Projects\KidneyNet\mlruns\0\60b5542ceef141a7a4077f71eb74bcea\artifacts\model\data\model\variables]
[2024-06-04 22:38:21,507: INFO: stage4_model_evaluation: >>>>>> stage Evaluation stage completed <<<<<<

x==========x]
[2024-06-09 21:58:48,437: INFO: _internal: [31m[1mWARNING: This is a development server. Do not use it in a production deployment. Use a production WSGI server instead.[0m
 * Running on all addresses (0.0.0.0)
 * Running on http://127.0.0.1:8080
 * Running on http://192.168.1.11:8080]
[2024-06-09 21:58:48,437: INFO: _internal: [33mPress CTRL+C to quit[0m]
[2024-06-09 21:59:11,128: INFO: _internal: 127.0.0.1 - - [09/Jun/2024 21:59:11] "GET / HTTP/1.1" 200 -]
[2024-06-09 22:11:29,915: INFO: _internal: [31m[1mWARNING: This is a development server. Do not use it in a production deployment. Use a production WSGI server instead.[0m
 * Running on all addresses (0.0.0.0)
 * Running on http://127.0.0.1:8080
 * Running on http://192.168.1.11:8080]
[2024-06-09 22:11:29,915: INFO: _internal: [33mPress CTRL+C to quit[0m]
[2024-06-09 22:11:39,002: INFO: _internal: 127.0.0.1 - - [09/Jun/2024 22:11:39] "GET / HTTP/1.1" 200 -]
[2024-06-09 22:15:51,082: INFO: _internal: [31m[1mWARNING: This is a development server. Do not use it in a production deployment. Use a production WSGI server instead.[0m
 * Running on all addresses (0.0.0.0)
 * Running on http://127.0.0.1:8080
 * Running on http://192.168.1.11:8080]
[2024-06-09 22:15:51,082: INFO: _internal: [33mPress CTRL+C to quit[0m]
[2024-06-09 22:15:54,653: INFO: _internal: 127.0.0.1 - - [09/Jun/2024 22:15:54] "GET / HTTP/1.1" 200 -]
[2024-06-09 22:16:36,866: ERROR: app: Exception on /predict [POST]]
Traceback (most recent call last):
  File "C:\Users\Sneha\anaconda3\envs\kidney\lib\site-packages\flask\app.py", line 2190, in wsgi_app
    response = self.full_dispatch_request()
  File "C:\Users\Sneha\anaconda3\envs\kidney\lib\site-packages\flask\app.py", line 1486, in full_dispatch_request
    rv = self.handle_user_exception(e)
  File "C:\Users\Sneha\anaconda3\envs\kidney\lib\site-packages\flask_cors\extension.py", line 176, in wrapped_function
    return cors_after_request(app.make_response(f(*args, **kwargs)))
  File "C:\Users\Sneha\anaconda3\envs\kidney\lib\site-packages\flask\app.py", line 1484, in full_dispatch_request
    rv = self.dispatch_request()
  File "C:\Users\Sneha\anaconda3\envs\kidney\lib\site-packages\flask\app.py", line 1469, in dispatch_request
    return self.ensure_sync(self.view_functions[rule.endpoint])(**view_args)
  File "C:\Users\Sneha\anaconda3\envs\kidney\lib\site-packages\flask_cors\decorator.py", line 130, in wrapped_function
    resp = make_response(f(*args, **kwargs))
  File "app.py", line 44, in predictRoute
    result = clApp.classifier.predict()
  File "c:\users\sneha\documents\projects\kidneynet\src\cnnClassifier\pipeline\prediction.py", line 12, in predict
    model = load_model(os.path.join("model", "model.h5"))
  File "C:\Users\Sneha\anaconda3\envs\kidney\lib\site-packages\keras\saving\saving_api.py", line 212, in load_model
    return legacy_sm_saving_lib.load_model(
  File "C:\Users\Sneha\anaconda3\envs\kidney\lib\site-packages\keras\utils\traceback_utils.py", line 70, in error_handler
    raise e.with_traceback(filtered_tb) from None
  File "C:\Users\Sneha\anaconda3\envs\kidney\lib\site-packages\keras\saving\legacy\save.py", line 230, in load_model
    raise IOError(
OSError: No file or directory found at model\model.h5
[2024-06-09 22:16:36,878: INFO: _internal: 127.0.0.1 - - [09/Jun/2024 22:16:36] "[35m[1mPOST /predict HTTP/1.1[0m" 500 -]
[2024-06-09 22:35:25,013: INFO: _internal: [31m[1mWARNING: This is a development server. Do not use it in a production deployment. Use a production WSGI server instead.[0m
 * Running on all addresses (0.0.0.0)
 * Running on http://127.0.0.1:8080
 * Running on http://192.168.1.11:8080]
[2024-06-09 22:35:25,013: INFO: _internal: [33mPress CTRL+C to quit[0m]
[2024-06-09 22:35:27,907: INFO: _internal: 127.0.0.1 - - [09/Jun/2024 22:35:27] "GET / HTTP/1.1" 200 -]
[2024-06-09 22:35:35,432: ERROR: app: Exception on /predict [POST]]
Traceback (most recent call last):
  File "C:\Users\Sneha\anaconda3\envs\kidney\lib\site-packages\flask\app.py", line 2190, in wsgi_app
    response = self.full_dispatch_request()
  File "C:\Users\Sneha\anaconda3\envs\kidney\lib\site-packages\flask\app.py", line 1486, in full_dispatch_request
    rv = self.handle_user_exception(e)
  File "C:\Users\Sneha\anaconda3\envs\kidney\lib\site-packages\flask_cors\extension.py", line 176, in wrapped_function
    return cors_after_request(app.make_response(f(*args, **kwargs)))
  File "C:\Users\Sneha\anaconda3\envs\kidney\lib\site-packages\flask\app.py", line 1484, in full_dispatch_request
    rv = self.dispatch_request()
  File "C:\Users\Sneha\anaconda3\envs\kidney\lib\site-packages\flask\app.py", line 1469, in dispatch_request
    return self.ensure_sync(self.view_functions[rule.endpoint])(**view_args)
  File "C:\Users\Sneha\anaconda3\envs\kidney\lib\site-packages\flask_cors\decorator.py", line 130, in wrapped_function
    resp = make_response(f(*args, **kwargs))
  File "app.py", line 44, in predictRoute
    result = clApp.classifier.predict()
  File "c:\users\sneha\documents\projects\kidneynet\src\cnnClassifier\pipeline\prediction.py", line 21, in predict
    result = np.argmax(model.predict(test_image), axis=1)
  File "C:\Users\Sneha\anaconda3\envs\kidney\lib\site-packages\keras\utils\traceback_utils.py", line 70, in error_handler
    raise e.with_traceback(filtered_tb) from None
  File "C:\Users\Sneha\AppData\Local\Temp\__autograph_generated_file47hrx220.py", line 15, in tf__predict_function
    retval_ = ag__.converted_call(ag__.ld(step_function), (ag__.ld(self), ag__.ld(iterator)), None, fscope)
ValueError: in user code:

    File "C:\Users\Sneha\anaconda3\envs\kidney\lib\site-packages\keras\engine\training.py", line 2169, in predict_function  *
        return step_function(self, iterator)
    File "C:\Users\Sneha\anaconda3\envs\kidney\lib\site-packages\keras\engine\training.py", line 2155, in step_function  **
        outputs = model.distribute_strategy.run(run_step, args=(data,))
    File "C:\Users\Sneha\anaconda3\envs\kidney\lib\site-packages\keras\engine\training.py", line 2143, in run_step  **
        outputs = model.predict_step(data)
    File "C:\Users\Sneha\anaconda3\envs\kidney\lib\site-packages\keras\engine\training.py", line 2111, in predict_step
        return self(x, training=False)
    File "C:\Users\Sneha\anaconda3\envs\kidney\lib\site-packages\keras\utils\traceback_utils.py", line 70, in error_handler
        raise e.with_traceback(filtered_tb) from None
    File "C:\Users\Sneha\anaconda3\envs\kidney\lib\site-packages\keras\engine\input_spec.py", line 298, in assert_input_compatibility
        raise ValueError(

    ValueError: Input 0 of layer "model" is incompatible with the layer: expected shape=(None, 299, 299, 3), found shape=(None, 224, 224, 3)

[2024-06-09 22:35:35,438: INFO: _internal: 127.0.0.1 - - [09/Jun/2024 22:35:35] "[35m[1mPOST /predict HTTP/1.1[0m" 500 -]
[2024-06-09 22:37:55,187: INFO: _internal: [31m[1mWARNING: This is a development server. Do not use it in a production deployment. Use a production WSGI server instead.[0m
 * Running on all addresses (0.0.0.0)
 * Running on http://127.0.0.1:8080
 * Running on http://192.168.1.11:8080]
[2024-06-09 22:37:55,188: INFO: _internal: [33mPress CTRL+C to quit[0m]
[2024-06-09 22:37:57,144: INFO: _internal: 127.0.0.1 - - [09/Jun/2024 22:37:57] "GET / HTTP/1.1" 200 -]
[2024-06-09 22:38:05,787: INFO: _internal: 127.0.0.1 - - [09/Jun/2024 22:38:05] "POST /predict HTTP/1.1" 200 -]
